<?xml version="1.0"?>
<robot name="RBY1_A_v1.2">
    <mobile type="differential" xyz="0.228 0 0" rpy="0 0 0" joints="right_wheel left_wheel"
        params="0.53 0.1" /> <!-- wheel_base, wheel_radius -->

    <link name="base">
        <inertial>
            <mass value="60.08042639" />
            <origin rpy="0 0 0" xyz="-0.06157942 -0.00142271 0.13513861" />
            <inertia ixx="1.37742174" ixy="0.02521789" ixz="0.18565467" iyy="2.99386515" iyz="-0.00641869"
                izz="3.76085052" />
        </inertial>

        <visual>
            <geometry>
                <mesh filename="file:///home/hsw/rby1_rviz/model/meshes/base.dae" />
            </geometry>
        </visual>
    </link>

    <link name="wheel_r">
        <inertial>
            <mass value="1.37783736" />
            <origin rpy="0 0 0" xyz="0.0 -0.00073938 0.0" />
            <inertia ixx="0.00426657" ixy="0.0" ixz="0.0" iyy="0.00811815" iyz="0.0" izz="0.00426657" />
        </inertial>

        <visual>
            <geometry>
                <mesh filename="file:///home/hsw/rby1_rviz/model/meshes/WHEEL.dae" />
            </geometry>
        </visual>
    </link>

    <link name="wheel_l">
        <inertial>
            <mass value="1.37783736" />
            <origin rpy="0 0 0" xyz="0.0 0.00073938 0.0" />
            <inertia ixx="0.00426657" ixy="0.0" ixz="0.0" iyy="0.00811815" iyz="0.0" izz="0.00426657" />
        </inertial>

        <visual>
            <geometry>
                <mesh filename="file:///home/hsw/rby1_rviz/model/meshes/WHEEL.dae" />
            </geometry>
        </visual>
    </link>

    <link name="link_torso_0">
        <inertial>
            <mass value="2.24282123" />
            <origin rpy="0 0 0" xyz="-0.08848415 0.00021367 0.00000046" />
            <inertia ixx="0.01413496" ixy="0.00092982" ixz="-0.00000010" iyy="0.01005357"
                iyz="-0.00000008" izz="0.01892525" />
        </inertial>

        <visual>
            <geometry>
                <mesh filename="file:///home/hsw/rby1_rviz/model/meshes/LINK_1.dae" />
            </geometry>
        </visual>

    </link>

    <link name="link_torso_1">
        <inertial>
            <mass value="9.72162676" />
            <origin rpy="0 0 0" xyz="0.00728955 -0.01728522 0.06911380" />
            <inertia ixx="0.14862640" ixy="-0.00142621" ixz="-0.00951385" iyy="0.13854733"
                iyz="-0.00975351" izz="0.02912982" />
        </inertial>

        <visual>
            <geometry>
                <mesh filename="file:///home/hsw/rby1_rviz/model/meshes/LINK_2.dae" />
            </geometry>
        </visual>

    </link>

    <link name="link_torso_2">
        <inertial>
            <mass value="9.21691850" />
            <origin rpy="0 0 0" xyz="0.00653835 -0.01769536 0.05636582" />
            <inertia ixx="0.12162270" ixy="-0.00127910" ixz="-0.00831678" iyy="0.11589190"
                iyz="-0.00873271" izz="0.03094484" />
        </inertial>

        <visual>
            <geometry>
                <mesh filename="file:///home/hsw/rby1_rviz/model/meshes/LINK_3.dae" />
            </geometry>
        </visual>

    </link>

    <link name="link_torso_3">
        <inertial>
            <mass value="4.18679196" />
            <origin rpy="0 0 0" xyz="-0.00574156 -0.01725975 0.00005610" />
            <inertia ixx="0.00849870" ixy="0.00040861" ixz="-0.00000263" iyy="0.00929513"
                iyz="-0.00001243" izz="0.00955442" />
        </inertial>

        <visual>
            <geometry>
                <mesh filename="file:///home/hsw/rby1_rviz/model/meshes/LINK_4.dae" />
            </geometry>
        </visual>
    </link>

    <link name="link_torso_4">
        <inertial>
            <mass value="4.45566276" />
            <origin rpy="0 0 0" xyz="-0.09097095 0.00005085 0.02601950" />
            <inertia ixx="0.01545991" ixy="0.00001883" ixz="-0.00780349" iyy="0.02550888" iyz="0.00000715"
                izz="0.01952563" />
        </inertial>

        <visual>
            <geometry>
                <mesh filename="file:///home/hsw/rby1_rviz/model/meshes/LINK_5.dae" />
            </geometry>
        </visual>

    </link>

    <link name="link_torso_5">
        <inertial>
            <mass value="14.73283950" />
            <origin rpy="0 0 0" xyz="-0.03419752 0.00073431 -0.02659420" />
            <inertia ixx="0.23934353" ixy="0.00158316" ixz="0.02926509" iyy="0.23140544" iyz="0.00018390"
                izz="0.18873182" />
        </inertial>

        <visual>
            <geometry>
                <mesh filename="file:///home/hsw/rby1_rviz/model/meshes/LINK_6.dae" />
            </geometry>
        </visual>

    </link>

    <link name="link_right_arm_0">
        <inertial>
            <mass value="1.26164242" />
            <origin rpy="0 0 0" xyz="-0.00316662 0.03437181 -0.00000030" />
            <inertia ixx="0.00230621" ixy="0.00039024" ixz="-0.00000256" iyy="0.00426418" iyz="0.00000118"
                izz="0.00432156" />
        </inertial>

        <visual>
            <geometry>
                <mesh filename="file:///home/hsw/rby1_rviz/model/meshes/LINK_7.dae" />
            </geometry>
        </visual>

    </link>

    <link name="link_right_arm_1">
        <inertial>
            <mass value="2.27287031" />
            <origin rpy="0 0 0" xyz="-0.00307855 -0.00124741 -0.01294324" />
            <inertia ixx="0.00388490" ixy="-0.00001477" ixz="0.00011465" iyy="0.00447034"
                iyz="-0.00010023" izz="0.00288341" />
        </inertial>

        <visual>
            <geometry>
                <mesh filename="file:///home/hsw/rby1_rviz/model/meshes/LINK_8.dae" />
            </geometry>
        </visual>

    </link>

    <link name="link_right_arm_2">
        <inertial>
            <mass value="2.46909439" />
            <origin rpy="0 0 0" xyz="0.00115434 0.00196635 -0.16192524" />
            <inertia ixx="0.00980269" ixy="0.00005871" ixz="0.00051888" iyy="0.00924560" iyz="-0.00045932"
                izz="0.00329867" />
        </inertial>

        <visual>
            <geometry>
                <mesh filename="file:///home/hsw/rby1_rviz/model/meshes/LINK_9.dae" />
            </geometry>
        </visual>

    </link>

    <link name="link_right_arm_3">
        <inertial>
            <mass value="2.26099493" />
            <origin rpy="0 0 0" xyz="-0.01603135 -0.00692891 -0.04549811" />
            <inertia ixx="0.00822606" ixy="0.00027620" ixz="-0.00156570" iyy="0.00844870" iyz="0.00076157"
                izz="0.00236614" />
        </inertial>

        <visual>
            <geometry>
                <mesh filename="file:///home/hsw/rby1_rviz/model/meshes/LINK_10.dae" />
            </geometry>
        </visual>

    </link>

    <link name="link_right_arm_4">
        <inertial>
            <mass value="0.42508710" />
            <origin rpy="0 0 0" xyz="-0.00000011 -0.02696036 0.06182110" />
            <inertia ixx="0.00082466" ixy="0.0" ixz="0.0" iyy="0.00075398" iyz="-0.00025338"
                izz="0.00039794" />
        </inertial>

        <visual>
            <geometry>
                <mesh filename="file:///home/hsw/rby1_rviz/model/meshes/LINK_11.dae" />
            </geometry>
        </visual>

    </link>

    <link name="link_right_arm_5">
        <inertial>
            <mass value="1.60506693" />
            <origin rpy="0 0 0" xyz="0.00592642 -0.00537804 -0.02584713" />
            <inertia ixx="0.00247557" ixy="-0.00004984" ixz="-0.00009861" iyy="0.00268241"
                iyz="0.00021452" izz="0.00166724" />
        </inertial>

        <visual>
            <geometry>
                <mesh filename="file:///home/hsw/rby1_rviz/model/meshes/LINK_12_v1.1.dae" />
            </geometry>
        </visual>
    </link>

    <link name="link_right_arm_6">
        <inertial>
            <mass value="0.42751673" />
            <origin rpy="0 0 0" xyz="0.00024951 -0.00019562 -0.10711314" />
            <inertia ixx="0.00029613" ixy="-0.00000186" ixz="-0.00000157" iyy="0.00030651"
                iyz="0.00000221" izz="0.00048946" />
        </inertial>

        <visual>
            <geometry>
                <mesh filename="file:///home/hsw/rby1_rviz/model/meshes/LINK_13_v1.1.dae" />
            </geometry>
        </visual>
    </link>

    <link name="link_left_arm_0">
        <inertial>
            <mass value="1.26164242"/>
            <origin rpy="0 0 0" xyz="-0.00316662 -0.03437181 -0.00000030"/>
            <inertia ixx="0.00230621" ixy="-0.00039024" ixz="0.00000256" iyy="0.00426418" iyz="0.00000118"
                     izz="0.00432156"/>
        </inertial>

        <visual>
            <geometry>
                <mesh filename="file:///home/hsw/rby1_rviz/model/meshes/LINK_14.dae" />
            </geometry>
        </visual>

    </link>

    <link name="link_left_arm_1">
        <inertial>
            <mass value="2.27287031" />
            <origin rpy="0 0 0" xyz="-0.00307855 0.00124741 -0.01294324" />
            <inertia ixx="0.00388490" ixy="-0.00001477" ixz="0.00011465" iyy="0.00447034" iyz="0.00010023"
                izz="0.00288341" />
        </inertial>

        <visual>
            <geometry>
                <mesh filename="file:///home/hsw/rby1_rviz/model/meshes/LINK_15.dae" />
            </geometry>
        </visual>
    </link>

    <link name="link_left_arm_2">
        <inertial>
            <mass value="2.46909439" />
            <origin rpy="0 0 0" xyz="0.00115434 -0.00196635 -0.16192524" />
            <inertia ixx="0.00980269" ixy="0.00005871" ixz="0.00051888" iyy="0.00924560" iyz="-0.00045932"
                izz="0.00329867" />
        </inertial>

        <visual>
            <geometry>
                <mesh filename="file:///home/hsw/rby1_rviz/model/meshes/LINK_16.dae" />
            </geometry>
        </visual>

    </link>

    <link name="link_left_arm_3">
        <inertial>
            <mass value="2.26099493" />
            <origin rpy="0 0 0" xyz="-0.01603135 0.00692891 -0.04549811" />
            <inertia ixx="0.00822606" ixy="-0.00027620" ixz="-0.00156570" iyy="0.00844870"
                iyz="-0.00076157" izz="0.00236614" />
        </inertial>

        <visual>
            <geometry>
                <mesh filename="file:///home/hsw/rby1_rviz/model/meshes/LINK_17.dae" />
            </geometry>
        </visual>

    </link>

    <link name="link_left_arm_4">
        <inertial>
            <mass value="0.42508710" />
            <origin rpy="0 0 0" xyz="0.00000011 0.02696036 0.06182110" />
            <inertia ixx="0.00082466" ixy="0.0" ixz="0.0" iyy="0.00075398" iyz="0.00025338"
                izz="0.00039794" />
        </inertial>

        <visual>
            <geometry>
                <mesh filename="file:///home/hsw/rby1_rviz/model/meshes/LINK_18.dae" />
            </geometry>
        </visual>

    </link>

    <link name="link_left_arm_5">
        <inertial>
            <mass value="1.60506693" />
            <origin rpy="0 0 0" xyz="0.00592642 -0.00537804 -0.02584713" />
            <inertia ixx="0.00247557" ixy="-0.00004984" ixz="-0.00009861" iyy="0.00268241"
                iyz="0.00021452" izz="0.00166724" />
        </inertial>

        <visual>
            <geometry>
                <mesh filename="file:///home/hsw/rby1_rviz/model/meshes/LINK_19_v1.1.dae" />
            </geometry>
        </visual>

    </link>

    <link name="link_left_arm_6">
        <inertial>
            <mass value="0.42751673" />
            <origin rpy="0 0 0" xyz="-0.00024951 0.00019562 -0.10711314" />
            <inertia ixx="0.00029613" ixy="-0.00000186" ixz="0.00000157" iyy="0.00030651"
                iyz="-0.00000221" izz="0.00048946" />
        </inertial>

        <visual>
            <geometry>
                <mesh filename="file:///home/hsw/rby1_rviz/model/meshes/LINK_20_v1.1.dae" />
            </geometry>
        </visual>
    </link>

    <link name="ee_right">
        <inertial>
            <mass value="0.46704998" />
            <origin rpy="0 0 0" xyz="0.00212703 0.00000615 -0.04287176" />
            <inertia ixx="0.00032067" ixy="0.00002383" ixz="-0.00000785" iyy="0.00059559"
                iyz="-0.00000007" izz="0.00052732" />
        </inertial>

        <visual>
            <geometry>
                <mesh filename="file:///home/hsw/rby1_rviz/model/meshes/EE_BODY.dae" />
            </geometry>
        </visual>
    </link>

    <link name="ee_finger_r1">
        <inertial>
            <mass value="0.03326999" />
            <origin rpy="0 0 0" xyz="0.00278346 -0.00000329 -0.02570112" />
            <inertia ixx="0.00001231" ixy="0.0" ixz="-0.00000042" iyy="0.00001066" iyz="0.0"
                izz="0.00000224" />
        </inertial>

        <visual>
            <geometry>
                <mesh filename="file:///home/hsw/rby1_rviz/model/meshes/EE_FINGER.dae" />
            </geometry>
        </visual>
    </link>

    <link name="ee_finger_r2">
        <inertial>
            <mass value="0.03326999" />
            <origin rpy="0 0 0" xyz="0.00278346 -0.00000329 -0.02570112" />
            <inertia ixx="0.00001231" ixy="0.0" ixz="-0.00000042" iyy="0.00001066" iyz="0.0"
                izz="0.00000224" />
        </inertial>

        <visual>
            <geometry>
                <mesh filename="file:///home/hsw/rby1_rviz/model/meshes/EE_FINGER.dae" />
            </geometry>
        </visual>
    </link>

    <link name="ee_left">
        <inertial>
            <mass value="0.46704998" />
            <origin rpy="0 0 0" xyz="0.00212703 0.00000615 -0.04287176" />
            <inertia ixx="0.00032067" ixy="0.00002383" ixz="-0.00000785" iyy="0.00059559"
                iyz="-0.00000007" izz="0.00052732" />
        </inertial>

        <visual>
            <geometry>
                <mesh filename="file:///home/hsw/rby1_rviz/model/meshes/EE_BODY.dae" />
            </geometry>
        </visual>
    </link>

    <link name="ee_finger_l1">
        <inertial>
            <mass value="0.03326999" />
            <origin rpy="0 0 0" xyz="0.00278346 -0.00000329 -0.02570112" />
            <inertia ixx="0.00001231" ixy="0.0" ixz="-0.00000042" iyy="0.00001066" iyz="0.0"
                izz="0.00000224" />
        </inertial>

        <visual>
            <geometry>
                <mesh filename="file:///home/hsw/rby1_rviz/model/meshes/EE_FINGER.dae" />
            </geometry>
        </visual>
    </link>

    <link name="ee_finger_l2">
        <inertial>
            <mass value="0.03326999" />
            <origin rpy="0 0 0" xyz="0.00278346 -0.00000329 -0.02570112" />
            <inertia ixx="0.00001231" ixy="0.0" ixz="-0.00000042" iyy="0.00001066" iyz="0.0"
                izz="0.00000224" />
        </inertial>

        <visual>
            <geometry>
                <mesh filename="file:///home/hsw/rby1_rviz/model/meshes/EE_FINGER.dae" />
            </geometry>
        </visual>
    </link>

    <link name="link_head_0">
        <inertial>
            <mass value="0.65731648" />
            <origin rpy="0 0 0" xyz="0.00024733 0.00033306 -0.01029730" />
            <inertia ixx="0.00046241" ixy="0.00000182" ixz="0.00001119" iyy="0.00043223" iyz="0.00000061"
                izz="0.00027509" />
        </inertial>

        <visual>
            <geometry>
                <mesh filename="file:///home/hsw/rby1_rviz/model/meshes/NECK_0.dae" />
            </geometry>
        </visual>
    </link>

    <link name="link_head_1">
        <inertial>
            <mass value="0.70476502" />
            <origin rpy="0 0 0" xyz="-0.00041643 0.00593524 -0.00289916" />
            <inertia ixx="0.00066212" ixy="-0.00000515" ixz="0.00000093" iyy="0.00036078"
                iyz="-0.00001312" izz="0.00059265" />
        </inertial>

        <visual>
            <geometry>
                <mesh filename="file:///home/hsw/rby1_rviz/model/meshes/NECK_1.dae" />
            </geometry>
        </visual>
    </link>

    <link name="link_head_2">
        <inertial>
            <mass value="0.95262738" />
            <origin rpy="0 0 0" xyz="0.05315320 0.00547509 0.05913909" />
            <inertia ixx="0.00114243" ixy="0.00027678" ixz="-0.00035426" iyy="0.00107559" iyz="0.00023641"
                izz="0.00151415" />
        </inertial>

        <visual>
            <geometry>
                <mesh filename="file:///home/hsw/rby1_rviz/model/meshes/NECK_2.dae" />
            </geometry>
        </visual>
    </link>


    <!-- Joints -->
    <joint name="right_wheel" type="continuous">
        <parent link="base" />
        <child link="wheel_r" />
        <origin rpy="0.0 0.0 0.0" xyz="0.228 -0.265 0.1" />
        <axis xyz="0 -1 0" />
        <limit effort="100.0" velocity="15.707963268" />
    </joint>

    <joint name="left_wheel" type="continuous">
        <parent link="base" />
        <child link="wheel_l" />
        <origin rpy="0.0 0.0 0.0" xyz="0.228 0.265 0.1" />
        <axis xyz="0 -1 0" />
        <limit effort="100.0" velocity="15.707963268" />
    </joint>

    <joint name="torso_0" type="revolute">
        <parent link="base" />
        <child link="link_torso_0" />
        <origin rpy="0.0 0.0 0.0" xyz="0.0 0.0 0.2805" />
        <axis xyz="1 0 0" />
        <!-- Nm, rad/s^2, rad/s, (min) rad, (max) rad -->
        <!-- 270Nm, 5rad/s^2, 120deg/s, -15deg, 15deg -->
        <limit effort="270.0"
            acceleration="5.0"
            velocity="2.09439510"
            lower="-0.261799388"
            upper="0.261799388"
        />
    </joint>

    <joint name="torso_1" type="revolute">
        <parent link="link_torso_0" />
        <child link="link_torso_1" />
        <origin rpy="0.0 0.0 0.0" xyz="0.0 0.0 0.0" />
        <axis xyz="0 1 0" />
        <!-- Nm, rad/s^2, rad/s, (min) rad, (max) rad -->
        <!-- 270Nm, 5rad/s^2, 120deg/s, -30deg, 90deg -->
        <limit effort="270.0"
            acceleration="5.0"
            velocity="2.09439510"
            lower="-0.523598776"
            upper="1.570796327"
        />
    </joint>

    <joint name="torso_2" type="revolute">
        <parent link="link_torso_1" />
        <child link="link_torso_2" />
        <origin rpy="0.0 0.0 0.0" xyz="0.0 0.0 0.350" />
        <axis xyz="0 1 0" />
        <!-- Nm, rad/s^2, rad/s, (min) rad, (max) rad -->
        <!-- 270Nm, 5rad/s^2, 120deg/s, -150deg, 90deg -->
        <limit effort="270.0"
            acceleration="5.0"
            velocity="2.09439510"
            lower="-2.617993878"
            upper="1.570796327"
        />
    </joint>

    <joint name="torso_3" type="revolute">
        <parent link="link_torso_2" />
        <child link="link_torso_3" />
        <origin rpy="0.0 0.0 0.0" xyz="0.0 0.0 0.350" />
        <axis xyz="0 1 0" />
        <!-- Nm, rad/s^2, rad/s, (min) rad, (max) rad -->
        <!-- 120Nm, 5rad/s^2, 180deg/s, -45deg, 90deg -->
        <limit effort="120.0"
            acceleration="5.0"
            velocity="3.141592654"
            lower="-0.785398163"
            upper="1.570796327"
        />
    </joint>

    <joint name="torso_4" type="revolute">
        <parent link="link_torso_3" />
        <child link="link_torso_4" />
        <origin rpy="0.0 0.0 0.0" xyz="0.0 0.0 0.0" />
        <axis xyz="1 0 0" />
        <!-- Nm, rad/s^2, rad/s, (min) rad, (max) rad -->
        <!-- 120Nm, 5rad/s^2, 180deg/s, -30deg, 30deg -->
        <limit effort="120.0"
            acceleration="5.0"
            velocity="3.141592654"
            lower="-0.523598776"
            upper="0.523598776"
        />
    </joint>

    <joint name="torso_5" type="revolute">
        <parent link="link_torso_4" />
        <child link="link_torso_5" />
        <origin rpy="0.0 0.0 0.0" xyz="0.0 0.0 0.309426548461" />
        <axis xyz="0 0 1" />
        <!-- Nm, rad/s^2, rad/s, (min) rad, (max) rad -->
        <!-- 120Nm, 5rad/s^2, 180deg/s, -135deg, 135deg -->
        <limit effort="120.0"
            acceleration="5.0"
            velocity="3.141592654"
            lower="-2.35619449"
            upper="2.35619449"
        />
    </joint>

    <joint name="right_arm_0" type="revolute">
        <parent link="link_torso_5" />
        <child link="link_right_arm_0" />
        <origin rpy="0.0 0.0 0.0" xyz="0.0 -0.220 0.080073451539 " />
        <axis xyz="0.0 0.93969262 -0.34202014" />
        <!-- Nm, rad/s^2, rad/s, (min) rad, (max) rad -->
        <!-- 70Nm, 10rad/s^2, 180deg/s, -180deg, 180deg -->
        <limit effort="70.0"
            acceleration="10.0"
            velocity="3.141592654"
            lower="-3.141592654"
            upper="1.570796327"
        />
    </joint>

    <joint name="right_arm_1" type="revolute">
        <parent link="link_right_arm_0" />
        <child link="link_right_arm_1" />
        <origin rpy="0.0 0.0 0.0" xyz="0.0 0.0 0.0" />
        <axis xyz="1 0 0" />
        <!-- Nm, rad/s^2, rad/s, (min) rad, (max) rad -->
        <!-- 70Nm, 10rad/s^2, 180deg/s, -180deg, 1deg -->
        <limit effort="70.0"
            acceleration="10.0"
            velocity="3.141592654"
            lower="-1.570796327"
            upper="0.0"
        />
    </joint>

    <joint name="right_arm_2" type="revolute">
        <parent link="link_right_arm_1" />
        <child link="link_right_arm_2" />
        <origin rpy="0.0 0.0 0.0" xyz="0.0 0.0 0.0" />
        <axis xyz="0 0 1" />
        <!-- Nm, rad/s^2, rad/s, (min) rad, (max) rad -->
        <!-- 70Nm, 10rad/s^2, 180deg/s, -180deg, 180deg -->
        <limit effort="70.0"
            acceleration="10.0"
            velocity="3.141592654"
            lower="-3.141592654"
            upper="3.141592654"
        />
    </joint>

    <joint name="right_arm_3" type="revolute">
        <parent link="link_right_arm_2" />
        <child link="link_right_arm_3" />
        <origin rpy="0.0 0.0 0.0" xyz="0.031 0.0 -0.276" />
        <axis xyz="0 1 0" />
        <!-- Nm, rad/s^2, rad/s, (min) rad, (max) rad -->
        <!-- 40Nm, 10rad/s^2, 180deg/s, -150deg, 1deg -->
        <limit effort="40.0"
            acceleration="10.0"
            velocity="3.141592654"
            lower="-2.617993878"
            upper="0.1"
        />
    </joint>

    <joint name="right_arm_4" type="revolute">
        <parent link="link_right_arm_3" />
        <child link="link_right_arm_4" />
        <origin rpy="0.0 0.0 0.0" xyz="-0.031 0.0 -0.256" />
        <axis xyz="0 0 1" />
        <!-- Nm, rad/s^2, rad/s, (min) rad, (max) rad -->
        <!-- 10Nm, 10rad/s^2, 360deg/s, -180deg, 180deg -->
        <limit effort="10.0"
            acceleration="10.0"
            velocity="6.283185308"
            lower="-3.141592654"
            upper="3.141592654"
        />
    </joint>

    <joint name="right_arm_5" type="revolute">
        <parent link="link_right_arm_4" />
        <child link="link_right_arm_5" />
        <origin rpy="0.0 0.0 0.0" xyz="0.0 0.0 0.0" />
        <axis xyz="0 1 0" />
        <!-- Nm, rad/s^2, rad/s, (min) rad, (max) rad -->
        <!-- 10Nm, 10rad/s^2, 360deg/s, -90deg, 110deg -->
        <limit effort="10.0"
            acceleration="10.0"
            velocity="6.283185308"
            lower="-1.570796327"
            upper="1.919862177"
        />
    </joint>

    <joint name="right_arm_6" type="revolute">
        <parent link="link_right_arm_5" />
        <child link="link_right_arm_6" />
        <origin rpy="0.0 0.0 0.0" xyz="0.0 0.0 0.0" />
        <axis xyz="0 0 1" />
        <!-- Nm, rad/s^2, rad/s, (min) rad, (max) rad -->
        <!-- 8Nm, 10rad/s^2, 120deg/s, -155deg, 155deg -->
        <limit effort="8.0"
            acceleration="10.0"
            velocity="2.094395102"
            lower="-2.705260340"
            upper="2.705260340"
        />
    </joint>

    <joint name="left_arm_0" type="revolute">
        <parent link="link_torso_5" />
        <child link="link_left_arm_0" />
        <origin rpy="0.0 0.0 0.0" xyz="0.0 0.220 0.080073452 " />
        <axis xyz="0.0 0.93969262 0.34202014" />
        <!-- Nm, rad/s^2, rad/s, (min) rad, (max) rad -->
        <!-- 70Nm, 10rad/s^2, 180deg/s, -180deg, 180deg -->
        <limit effort="70.0"
            acceleration="10.0"
            velocity="3.141592654"
            lower="-3.141592654"
            upper="1.570796327"
        />
    </joint>

    <joint name="left_arm_1" type="revolute">
        <parent link="link_left_arm_0" />
        <child link="link_left_arm_1" />
        <origin rpy="0.0 0.0 0.0" xyz="0.0 0.0 0.0" />
        <axis xyz="1 0 0" />
        <!-- Nm, rad/s^2, rad/s, (min) rad, (max) rad -->
        <!-- 70Nm, 10rad/s^2, 180deg/s, -1deg, 180deg -->
        <limit effort="70.0"
            acceleration="10.0"
            velocity="3.141592654"
            lower="0.0"
            upper="1.570796327"
        />
    </joint>

    <joint name="left_arm_2" type="revolute">
        <parent link="link_left_arm_1" />
        <child link="link_left_arm_2" />
        <origin rpy="0.0 0.0 0.0" xyz="0.0 0.0 0.0" />
        <axis xyz="0 0 1" />
        <!-- Nm, rad/s^2, rad/s, (min) rad, (max) rad -->
        <!-- 70Nm, 10rad/s^2, 180deg/s, -180deg, 180deg -->
        <limit effort="70.0"
            acceleration="10.0"
            velocity="3.141592654"
            lower="-3.141592654"
            upper="3.141592654"
        />
    </joint>

    <joint name="left_arm_3" type="revolute">
        <parent link="link_left_arm_2" />
        <child link="link_left_arm_3" />
        <origin rpy="0.0 0.0 0.0" xyz="0.031 0.0 -0.276" />
        <axis xyz="0 1 0" />
        <!-- Nm, rad/s^2, rad/s, (min) rad, (max) rad -->
        <!-- 40Nm, 10rad/s^2, 180deg/s, -150deg, 1deg -->
        <limit effort="40.0"
            acceleration="10.0"
            velocity="3.141592654"
            lower="-2.617993878"
            upper="0.1"
        />
    </joint>

    <joint name="left_arm_4" type="revolute">
        <parent link="link_left_arm_3" />
        <child link="link_left_arm_4" />
        <origin rpy="0.0 0.0 0.0" xyz="-0.031 0.0 -0.256" />
        <axis xyz="0 0 1" />
        <!-- Nm, rad/s^2, rad/s, (min) rad, (max) rad -->
        <!-- 10Nm, 10rad/s^2, 360deg/s, -180deg, 180deg -->
        <limit effort="10.0"
            acceleration="10.0"
            velocity="6.283185308"
            lower="-3.141592654"
            upper="3.141592654"
        />
    </joint>

    <joint name="left_arm_5" type="revolute">
        <parent link="link_left_arm_4" />
        <child link="link_left_arm_5" />
        <origin rpy="0.0 0.0 0.0" xyz="0.0 0.0 0.0" />
        <axis xyz="0 1 0" />
        <!-- Nm, rad/s^2, rad/s, (min) rad, (max) rad -->
        <!-- 10Nm, 10rad/s^2, 360deg/s, -90deg, 110deg -->
        <limit effort="10.0"
            acceleration="10.0"
            velocity="6.283185308"
            lower="-1.570796327"
            upper="1.919862177"
        />
    </joint>

    <joint name="left_arm_6" type="revolute">
        <parent link="link_left_arm_5" />
        <child link="link_left_arm_6" />
        <origin rpy="0.0 0.0 0.0" xyz="0.0 0.0 0.0" />
        <axis xyz="0 0 1" />
        <!-- Nm, rad/s^2, rad/s, (min) rad, (max) rad -->
        <!-- 8Nm, 10rad/s^2, 120deg/s, -155deg, 155deg -->
        <limit effort="8.0"
            acceleration="10.0"
            velocity="2.094395102"
            lower="-2.705260340"
            upper="2.705260340"
        />
    </joint>

    <joint name="tool_right" type="fixed">
        <parent link="link_right_arm_6" />
        <child link="ee_right" />
        <origin rpy="0.0 0.0 0.0" xyz="0.0 0.0 -0.1611" />
        <axis xyz="0 0 1" />
    </joint>

    <joint name="gripper_finger_r1" type="prismatic" in_model_type="fixed">
        <parent link="ee_right" />
        <child link="ee_finger_r1" />
        <origin rpy="0.0 0.0 0.0" xyz="0.003 0.0 -0.075" />
        <axis xyz="-1 0 0" />
        <limit effort="1000" velocity="0.05" lower="-0.05" upper="0" />
    </joint>

    <joint name="gripper_finger_r2" type="prismatic" in_model_type="fixed">
        <parent link="ee_right" />
        <child link="ee_finger_r2" />
        <origin rpy="0.0 0.0 3.1415926535" xyz="-0.003 0.0 -0.075" />
        <axis xyz="1 0 0" />
        <limit effort="1000" velocity="0.05" lower="0" upper="0.05" />
    </joint>

    <joint name="tool_left" type="fixed">
        <parent link="link_left_arm_6" />
        <child link="ee_left" />
        <origin rpy="0.0 0.0 0" xyz="0.0 0.0 -0.1611" />
        <axis xyz="0 0 1" />
    </joint>

    <joint name="gripper_finger_l1" type="prismatic" in_model_type="fixed">
        <parent link="ee_left" />
        <child link="ee_finger_l1" />
        <origin rpy="0.0 0.0 0.0" xyz="0.003 0.0 -0.075" />
        <axis xyz="-1 0 0" />
        <limit effort="1000" velocity="0.05" lower="-0.05" upper="0" />
    </joint>

    <joint name="gripper_finger_l2" type="prismatic" in_model_type="fixed">
        <parent link="ee_left" />
        <child link="ee_finger_l2" />
        <origin rpy="0.0 0.0 3.1415926535" xyz="-0.003 0.0 -0.075" />
        <axis xyz="1 0 0" />
        <limit effort="1000" velocity="0.05" lower="0" upper="0.05" />
    </joint>

    <joint name="head_base" type="fixed">
        <parent link="link_torso_5" />
        <child link="link_head_0" />
        <origin rpy="0.0 0.0 0.0" xyz="0.022 0.0 0.120073451525" />
        <axis xyz="0 0 1" />
    </joint>

    <joint name="head_0" type="revolute">
        <parent link="link_head_0" />
        <child link="link_head_1" />
        <origin rpy="0.0 0.0 0.0" xyz="0.0 0.0 0.080" />
        <axis xyz="0 0 1" />
        <limit effort="1000" velocity="3.14" lower="-1.57" upper="1.57" />
    </joint>

    <joint name="head_1" type="revolute">
        <parent link="link_head_1" />
        <child link="link_head_2" />
        <origin rpy="0.0 0.0 0.0" xyz="0.0 0.0 0.0" />
        <axis xyz="0 1 0" />
        <limit effort="1000" velocity="3.14" lower="-1.57" upper="1.57" />
    </joint>

    <link name="link_head_2_offset">
        <visual>
            <origin rpy="0 0 0" xyz="0 0 0" />
            <geometry>
                <box size="0.02 0.02 0.02" />
            </geometry>
            <material name="red">
                <color rgba="1 0 0 1"/>
            </material>
        </visual>
    </link>

    <joint name="head_2_to_offset" type="fixed">
        <parent link="link_head_2" />
        <child link="link_head_2_offset" />
        <origin xyz="0.07678 0.0 0.002676" rpy="0.0 0.2286381 0.0" />
    </joint>

    <link name="zed2i_right_camera_optical_frame" />
    <joint name="zed2i_right_camera_optical_joint" type="fixed">
        <parent link="link_head_2_offset" />
        <child link="zed2i_right_camera_optical_frame" />
        
        <origin xyz="0 -0.060 0" rpy="-1.5708 0 -1.5708" />
    </joint>

    <link name="zed2i_left_camera_optical_frame" />
    <joint name="zed2i_left_camera_optical_joint" type="fixed">
        <parent link="link_head_2_offset" />
        <child link="zed2i_left_camera_optical_frame" />
        <origin xyz="0 0.060 0" rpy="-1.5708 0 -1.5708" />
    </joint>

    <!-- <joint name="head_mount" type="fixed">
      <parent link="link_head_2"/>
      <child link="Arbitrary device"/>
      <origin rpy="0.0 0.0 0.0" xyz="0.022 0.0 0.04"/>
      <axis xyz="0 0 1"/>
    </joint> -->

</robot>